<?xml version="1.0"?>
<robot name="fridge_10905">
  <link name="base_link">
    <inertial>
      <origin xyz="0 0 0" rpy="0 0 0"/>
      <mass value="1"/>
      <inertia ixx="0.001" ixy="0" ixz="0" iyy="0.001" iyz="0" izz="0.001"/>
    </inertial>
    <visual>
      <origin xyz="0 0 0" rpy="0 0 0"/>
      <geometry>
        <mesh filename="meshes/base_link.obj" scale="1 1 1"/>
      </geometry>
    </visual>
    <collision>
      <origin xyz="0 0 0" rpy="0 0 0"/>
      <geometry>
        <mesh filename="meshes/base_link.obj" scale="1 1 1"/>
      </geometry>
    </collision>
  </link>
  <link name="moving_link">
    <inertial>
      <origin xyz="0 0 0" rpy="0 0 0"/>
      <mass value="1"/>
      <inertia ixx="0.001" ixy="0" ixz="0" iyy="0.001" iyz="0" izz="0.001"/>
    </inertial>
    <visual>
      <origin xyz="-0.2269176667 0.1669124355 -0.456948" rpy="0 0 0"/>
      <geometry>
        <mesh filename="meshes/moving_link.obj" scale="1 1 1"/>
      </geometry>
    </visual>
    <collision>
      <origin xyz="-0.2269176667 0.1669124355 -0.456948" rpy="0 0 0"/>
      <geometry>
        <mesh filename="meshes/moving_link.obj" scale="1 1 1"/>
      </geometry>
    </collision>
  </link>
  <joint name="fridge_10905_joint" type="revolute">
    <parent link="base_link"/>
    <child link="moving_link"/>
    <origin xyz="0.2269176667 -0.1669124355 0.456948" rpy="0 0 0"/>
    <axis xyz="0 0 1"/>
    <limit lower="-1.0471975512" upper="0" effort="100" velocity="10"/>
  </joint>
</robot>
