<?xml version="1.0"?>
<robot name="storage_45135">
  <link name="base_link">
    <inertial>
      <origin xyz="0 0 0" rpy="0 0 0"/>
      <mass value="1"/>
      <inertia ixx="0.001" ixy="0" ixz="0" iyy="0.001" iyz="0" izz="0.001"/>
    </inertial>
    <visual>
      <origin xyz="0 0 0" rpy="0 0 0"/>
      <geometry>
        <mesh filename="meshes/base_link.obj" scale="1 1 1"/>
      </geometry>
    </visual>
    <collision>
      <origin xyz="0 0 0" rpy="0 0 0"/>
      <geometry>
        <mesh filename="meshes/base_link.obj" scale="1 1 1"/>
      </geometry>
    </collision>
  </link>
  <link name="moving_link">
    <inertial>
      <origin xyz="0 0 0" rpy="0 0 0"/>
      <mass value="1"/>
      <inertia ixx="0.001" ixy="0" ixz="0" iyy="0.001" iyz="0" izz="0.001"/>
    </inertial>
    <visual>
      <origin xyz="0.0145976924 0.3823210001 -0.1355939233" rpy="0 0 0"/>
      <geometry>
        <mesh filename="meshes/moving_link.obj" scale="1 1 1"/>
      </geometry>
    </visual>
    <collision>
      <origin xyz="0.0145976924 0.3823210001 -0.1355939233" rpy="0 0 0"/>
      <geometry>
        <mesh filename="meshes/moving_link.obj" scale="1 1 1"/>
      </geometry>
    </collision>
  </link>
  <joint name="storage_45135_joint" type="prismatic">
    <parent link="base_link"/>
    <child link="moving_link"/>
    <origin xyz="-0.0145976924 -0.3823210001 0.1355939233" rpy="0 0 0"/>
    <axis xyz="0 -1 0"/>
    <limit lower="0" upper="0.3" effort="100" velocity="10"/>
  </joint>
</robot>
