<?xml version="1.0"?>
<robot name="washer_103776">
  <link name="base_link">
    <inertial>
      <origin xyz="0 0 0" rpy="0 0 0"/>
      <mass value="1"/>
      <inertia ixx="0.001" ixy="0" ixz="0" iyy="0.001" iyz="0" izz="0.001"/>
    </inertial>
    <visual>
      <origin xyz="0 0 0" rpy="0 0 0"/>
      <geometry>
        <mesh filename="meshes/base_link.obj" scale="1 1 1"/>
      </geometry>
    </visual>
    <collision>
      <origin xyz="0 0 0" rpy="0 0 0"/>
      <geometry>
        <mesh filename="meshes/base_link.obj" scale="1 1 1"/>
      </geometry>
    </collision>
  </link>
  <link name="moving_link">
    <inertial>
      <origin xyz="0 0 0" rpy="0 0 0"/>
      <mass value="1"/>
      <inertia ixx="0.001" ixy="0" ixz="0" iyy="0.001" iyz="0" izz="0.001"/>
    </inertial>
    <visual>
      <origin xyz="0 -0.1994985764 -0.535525318" rpy="0 0 0"/>
      <geometry>
        <mesh filename="meshes/moving_link.obj" scale="1 1 1"/>
      </geometry>
    </visual>
    <collision>
      <origin xyz="0 -0.1994985764 -0.535525318" rpy="0 0 0"/>
      <geometry>
        <mesh filename="meshes/moving_link.obj" scale="1 1 1"/>
      </geometry>
    </collision>
  </link>
  <joint name="washer_103776_joint" type="revolute">
    <parent link="base_link"/>
    <child link="moving_link"/>
    <origin xyz="0 0.1994985764 0.535525318" rpy="0 0 0"/>
    <axis xyz="1 0 0"/>
    <limit lower="-0.5235987756" upper="0" effort="100" velocity="10"/>
  </joint>
</robot>
